<?xml version="1.0" encoding="utf-8"?>
<!-- This URDF was automatically created by SolidWorks to URDF Exporter! Originally created by Stephen Brawner (brawner@gmail.com) 
     Commit Version: 1.5.1-0-g916b5db  Build Version: 1.5.7152.31018
     For more information, please see http://wiki.ros.org/sw_urdf_exporter -->
<robot name="liukuhihna_gazebo">

	<link name="world" />

	<joint name="fixed" type="fixed">
		<parent link="world"/>
		<child link="belt_visual"/>
		<origin xyz="0.0 0.0 0.0" rpy="0.0 0.0 0"/>
	</joint>
	

	<link name="belt_visual">
		<inertial>
			<origin xyz="1.1327E-16 -3.3286E-17 0.66019" rpy="0 0 0" />
			<mass value="71.953" />
			<inertia ixx="7.5972" ixy="-1.394E-14" ixz="1.9328E-17" iyy="0.99673" iyz="-9.2056E-18" izz="8.1168" />
		</inertial>
		<visual>
			<origin xyz="0 0 0" rpy="0 0 0" />
			<geometry>
				<mesh filename="package://demo_world/meshes/conveyor_belt.stl" scale="1 2 1"/>
			</geometry>
			<material name="white">
				<color rgba="1 1 1 1" />
			</material>
		</visual>
		<collision>
			<origin xyz="0.0 0.0 0" rpy="1.570796327 0.0 1.570796327"/>
			<geometry>
				<mesh filename="package://demo_world/meshes/conveyor_simple.stl" scale="1 2 1" />
			</geometry>
		</collision>
	</link>

	<gazebo reference="belt_visual">
		<material>Gazebo/Gray</material>
	</gazebo>


	<!-- <link name="test_cube">
		<visual>
			<origin xyz="0.0 0.0 0.37" rpy="0.0 0.0 0.0"/>
			<geometry>
				<box size="0.463 1.2 0.74"/>
			</geometry>
			<material name="purple">
				<color rgba="1 0 1 0.2" />
			</material>
		</visual>
	</link> -->

	<joint name="belt_joint" type="prismatic">
		<origin xyz="0.0 0.0 0.74" rpy="0.0 0.0 0.0"/>
		<parent link="belt_visual"/>
		<child link="belt_moving"/>
		<axis xyz="0 1 0"/>
		<limit lower="-1" upper="1" effort="1000" velocity="1000"/>
	</joint>

	<link name="belt_moving">
		<inertial>
			<origin xyz="0.0 0.0 0.0" rpy="0.0 0.0 0.0"/>
			<mass value="100"/>
			<inertia ixx="0.0" ixy="0.0" ixz="0.0" iyy="0.0" iyz="0.0" izz="0.0"/>
		</inertial>
		<!-- <visual>
			<origin xyz="0.0 0.0 0.0005" rpy="0.0 0.0 0.0"/>
			<geometry>
				<box size="0.425 2.4 0.001"/>
			</geometry>
			<material name="test">
				<color rgba="1 0 0 1" />
			</material>
		</visual> -->
		<collision>
			<origin xyz="0.0 0.0 0.0005" rpy="0.0 0.0 0.0"/>
			<geometry>
				<box size="0.425 2.4 0.001"/>
			</geometry>
		</collision>
	</link>

	<gazebo>
		<plugin name="conveyor_belt_plugin" filename="libROSConveyorBeltPlugin.so">
			<robot_namespace>/</robot_namespace>
			<link>belt_moving</link>
			<power>0</power>
			<max_velocity>1.0</max_velocity>
		</plugin>
	</gazebo>
	

	<joint name="camera_joint" type="fixed">
		<axis xyz="0 1 0" />
		<origin xyz="0.05 0 2.5" rpy="0 1.57 0"/>
		<parent link="belt_visual"/>
		<child link="camera_link"/>
	</joint>

	<!-- Camera -->
	<link name="camera_link">
		<collision>
			<origin xyz="0 0 0" rpy="0 0 0"/>
			<geometry>
				<box size="0.05 0.05 0.05"/>
			</geometry>
		</collision>

		<visual>
			<origin xyz="0 0 0" rpy="0 0 0"/>
			<geometry>
				<box size="0.05 0.05 0.05"/>
			</geometry>
			<material name="red"/>
		</visual>

		<inertial>
			<mass value="1e-5" />
			<origin xyz="0 0 0" rpy="0 0 0"/>
			<inertia ixx="1e-6" ixy="0" ixz="0" iyy="1e-6" iyz="0" izz="1e-6" />
		</inertial>
	</link>

	<!-- camera -->
	<gazebo reference="camera_link">
		<sensor type="camera" name="camera1">
		<update_rate>30.0</update_rate>
		<camera name="head">
			<horizontal_fov>1.3962634</horizontal_fov>
			<image>
			<width>800</width>
			<height>800</height>
			<format>R8G8B8</format>
			</image>
			<clip>
			<near>0.02</near>
			<far>300</far>
			</clip>
			<noise>
			<type>gaussian</type>
			<!-- Noise is sampled independently per pixel on each frame.
				That pixel's noise value is added to each of its color
				channels, which at that point lie in the range [0,1]. -->
			<mean>0.0</mean>
			<stddev>0.007</stddev>
			</noise>
		</camera>
		<plugin name="camera_controller" filename="libgazebo_ros_camera.so">
			<alwaysOn>true</alwaysOn>
			<updateRate>0.0</updateRate>
			<cameraName>/camera1</cameraName>
			<imageTopicName>image_raw</imageTopicName>
			<cameraInfoTopicName>camera_info</cameraInfoTopicName>
			<frameName>camera_link</frameName>
			<hackBaseline>0.07</hackBaseline>
			<distortionK1>0.0</distortionK1>
			<distortionK2>0.0</distortionK2>
			<distortionK3>0.0</distortionK3>
			<distortionT1>0.0</distortionT1>
			<distortionT2>0.0</distortionT2>
		</plugin>
		</sensor>
	</gazebo>
</robot>